Workbook

Sheet startup_table
A1: RD_Spend | B1: Administration | C1: Marketing_Spend | D1: State | E1: Profit | H1: Marketing_Spend | I1: State | J1: Profit
A2: 165349.2 | B2: 136897.8 | C2: 471784.1 | D2: New York | E2: 192261.83 | H2: 471784.1 | I2: New York | J2: 192261.83
A3: 162597.7 | B3: 151377.59 | C3: 443898.53 | D3: California | E3: 191792.06 | H3: 443898.53 | I3: California | J3: 191792.06
A4: 153441.51 | B4: 101145.55 | C4: 407934.54 | D4: Florida | E4: 191050.39 | H4: 407934.54 | I4: Florida | J4: 191050.39
A5: 144372.41 | B5: 118671.85 | C5: 383199.62 | D5: New York | E5: 182901.99 | H5: 383199.62 | I5: New York | J5: 182901.99
A6: 142107.34 | B6: 91391.77 | C6: 366168.42 | D6: Florida | E6: 166187.94 | H6: 366168.42 | I6: Florida | J6: 166187.94
A7: 131876.9 | B7: 99814.71 | C7: 362861.36 | D7: New York | E7: 156991.12 | H7: 362861.36 | I7: New York | J7: 156991.12
A8: 134615.46 | B8: 147198.87 | C8: 127716.82 | D8: California | E8: 156122.51 | H8: 127716.82 | I8: California | J8: 156122.51
A9: 130298.13 | B9: 145530.06 | C9: 323876.68 | D9: Florida | E9: 155752.6 | H9: 323876.68 | I9: Florida | J9: 155752.6 | R9: Marketing_Spend | S9: State | T9: Profit
A10: 120542.52 | B10: 148718.95 | C10: 311613.29 | D10: New York | E10: 152211.77 | H10: 311613.29 | I10: New York | J10: 152211.77 | R10: 471784.1 | S10: New York | T10: 192261.83
A11: 123334.88 | B11: 108679.17 | C11: 304981.62 | D11: California | E11: 149759.96 | H11: 304981.62 | I11: California | J11: 149759.96 | R11: 443898.53 | S11: California | T11: 191792.06
A12: 101913.08 | B12: 110594.11 | C12: 229160.95 | D12: Florida | E12: 146121.95 | H12: 229160.95 | I12: Florida | J12: 146121.95 | R12: 407934.54 | S12: Florida | T12: 191050.39
A13: 100671.96 | B13: 91790.61 | C13: 249744.55 | D13: California | E13: 144259.4 | H13: 249744.55 | I13: California | J13: 144259.4 | R13: 383199.62 | S13: New York | T13: 182901.99
A14: 93863.75 | B14: 127320.38 | C14: 249839.44 | D14: Florida | E14: 141585.52 | H14: 249839.44 | I14: Florida | J14: 141585.52 | R14: 366168.42 | S14: Florida | T14: 166187.94
A15: 91992.39 | B15: 135495.07 | C15: 252664.93 | D15: California | E15: 134307.35 | H15: 252664.93 | I15: California | J15: 134307.35 | R15: 362861.36 | S15: New York | T15: 156991.12
A16: 119943.24 | B16: 156547.42 | C16: 256512.92 | D16: Florida | E16: 132602.65 | R16: 127716.82 | S16: California | T16: 156122.51
A17: 114523.61 | B17: 122616.84 | C17: 261776.23 | D17: New York | E17: 129917.04 | O17: Marketing_Spend | P17: State | Q17: Profit | R17: 323876.68 | S17: Florida | T17: 155752.6
A18: 78013.11 | B18: 121597.55 | C18: 264346.06 | D18: California | E18: 126992.93 | O18: 471784.1 | P18: New York | Q18: 192261.83 | R18: 311613.29 | S18: New York | T18: 152211.77
A19: 94657.16 | B19: 145077.58 | C19: 282574.31 | D19: New York | E19: 125370.37 | O19: 443898.53 | P19: California | Q19: 191792.06 | R19: 304981.62 | S19: California | T19: 149759.96
A20: 91749.16 | B20: 114175.79 | C20: 294919.57 | D20: Florida | E20: 124266.9 | O20: 407934.54 | P20: Florida | Q20: 191050.39 | R20: 229160.95 | S20: Florida | T20: 146121.95
A21: 86419.7 | B21: 153514.11 | C21: 0 | D21: New York | E21: 122776.86 | O21: 383199.62 | P21: New York | Q21: 182901.99 | R21: 249744.55 | S21: California | T21: 144259.4
A22: 76253.86 | B22: 113867.3 | C22: 298664.47 | D22: California | E22: 118474.03 | O22: 366168.42 | P22: Florida | Q22: 166187.94 | R22: 249839.44 | S22: Florida | T22: 141585.52
A23: 78389.47 | B23: 153773.43 | C23: 299737.29 | D23: New York | E23: 111313.02 | O23: 362861.36 | P23: New York | Q23: 156991.12 | R23: 252664.93 | S23: California | T23: 134307.35
A24: 73994.56 | B24: 122782.75 | C24: 303319.26 | D24: Florida | E24: 110352.25 | O24: 127716.82 | P24: California | Q24: 156122.51
A25: 67532.53 | B25: 105751.03 | C25: 304768.73 | D25: Florida | E25: 108733.99 | O25: 323876.68 | P25: Florida | Q25: 155752.6
A26: 77044.01 | B26: 99281.34 | C26: 140574.81 | D26: New York | E26: 108552.04 | O26: 311613.29 | P26: New York | Q26: 152211.77
A27: 64664.71 | B27: 139553.16 | C27: 137962.62 | D27: California | E27: 107404.34 | O27: 304981.62 | P27: California | Q27: 149759.96
A28: 75328.87 | B28: 144135.98 | C28: 134050.07 | D28: Florida | E28: 105733.54 | O28: 229160.95 | P28: Florida | Q28: 146121.95
A29: 72107.6 | B29: 127864.55 | C29: 353183.81 | D29: New York | E29: 105008.31 | O29: 249744.55 | P29: California | Q29: 144259.4
A30: 66051.52 | B30: 182645.56 | C30: 118148.2 | D30: Florida | E30: 103282.38 | O30: 249839.44 | P30: Florida | Q30: 141585.52
A31: 65605.48 | B31: 153032.06 | C31: 107138.38 | D31: New York | E31: 101004.64 | O31: 252664.93 | P31: California | Q31: 134307.35
A32: 61994.48 | B32: 115641.28 | C32: 91131.24 | D32: Florida | E32: 99937.59
A33: 61136.38 | B33: 152701.92 | C33: 88218.23 | D33: New York | E33: 97483.56
A34: 63408.86 | B34: 129219.61 | C34: 46085.25 | D34: California | E34: 97427.84
A35: 55493.95 | B35: 103057.49 | C35: 214634.81 | D35: Florida | E35: 96778.92
A36: 46426.07 | B36: 157693.92 | C36: 210797.67 | D36: California | E36: 96712.8
A37: 46014.02 | B37: 85047.44 | C37: 205517.64 | D37: New York | E37: 96479.51
A38: 28663.76 | B38: 127056.21 | C38: 201126.82 | D38: Florida | E38: 90708.19
A39: 44069.95 | B39: 51283.14 | C39: 197029.42 | D39: California | E39: 89949.14
A40: 20229.59 | B40: 65947.93 | C40: 185265.1 | D40: New York | E40: 81229.06
...

Sheet Outliers
A1: 1. Get data from the database with the given credentials.
A2: 2. Perform Regression Analysis for the given data to identify how the money spent on Marketing, R&D, and Administration is affecting the company’s Profit. Predict the Profit for the below-given input features.
A4: R&D Spend | B4: Administration | C4: Marketing Spend | D4: Profit | F4: Mean of profit | G4: =AVERAGE(E13:E62) -> 112012.64 | I4: Standard Dev | J4: =STDEV(E13:E62) -> 40306.18
A5: 21892.92 | B5: 81910.77 | C5: 164270.7
A6: 23940.93 | B6: 96489.63 | C6: 137001.1
A12: RD_Spend | B12: Administration | C12: Marketing_Spend | D12: State | E12: Profit | F12: Outlier? | G12: Q1 | H12: Q3 | I12: IQR | J12: Upper bound | K12: Lower bound
A13: 165349.2 | B13: 136897.8 | C13: 471784.1 | D13: New York | E13: 192261.83 | F13: =OR(Outliers!E13>Outliers!$J$13,Outliers!E13<Outliers!$K$13) -> FALSE | G13: =QUARTILE(E13:E62,1) -> 90138.902 | H13: =QUARTILE(E13:E62,3) -> 139765.98 | I13: =H13-G13 -> 49627.075 | J13: =H13+(1.5*I13) -> 214206.59 | K13: =G13-(1.5*I13) -> 15698.29
A14: 162597.7 | B14: 151377.59 | C14: 443898.53 | D14: California | E14: 191792.06 | F14: =OR(Outliers!E14>Outliers!$J$13,Outliers!E14<Outliers!$K$13) -> FALSE
A15: 153441.51 | B15: 101145.55 | C15: 407934.54 | D15: Florida | E15: 191050.39 | F15: =OR(Outliers!E15>Outliers!$J$13,Outliers!E15<Outliers!$K$13) -> FALSE
A16: 144372.41 | B16: 118671.85 | C16: 383199.62 | D16: New York | E16: 182901.99 | F16: =OR(Outliers!E16>Outliers!$J$13,Outliers!E16<Outliers!$K$13) -> FALSE
A17: 142107.34 | B17: 91391.77 | C17: 366168.42 | D17: Florida | E17: 166187.94 | F17: =OR(Outliers!E17>Outliers!$J$13,Outliers!E17<Outliers!$K$13) -> FALSE
A18: 131876.9 | B18: 99814.71 | C18: 362861.36 | D18: New York | E18: 156991.12 | F18: =OR(Outliers!E18>Outliers!$J$13,Outliers!E18<Outliers!$K$13) -> FALSE
A19: 134615.46 | B19: 147198.87 | C19: 127716.82 | D19: California | E19: 156122.51 | F19: =OR(Outliers!E19>Outliers!$J$13,Outliers!E19<Outliers!$K$13) -> FALSE
A20: 130298.13 | B20: 145530.06 | C20: 323876.68 | D20: Florida | E20: 155752.6 | F20: =OR(Outliers!E20>Outliers!$J$13,Outliers!E20<Outliers!$K$13) -> FALSE
A21: 120542.52 | B21: 148718.95 | C21: 311613.29 | D21: New York | E21: 152211.77 | F21: =OR(Outliers!E21>Outliers!$J$13,Outliers!E21<Outliers!$K$13) -> FALSE
A22: 123334.88 | B22: 108679.17 | C22: 304981.62 | D22: California | E22: 149759.96 | F22: =OR(Outliers!E22>Outliers!$J$13,Outliers!E22<Outliers!$K$13) -> FALSE
A23: 101913.08 | B23: 110594.11 | C23: 229160.95 | D23: Florida | E23: 146121.95 | F23: =OR(Outliers!E23>Outliers!$J$13,Outliers!E23<Outliers!$K$13) -> FALSE
A24: 100671.96 | B24: 91790.61 | C24: 249744.55 | D24: California | E24: 144259.4 | F24: =OR(Outliers!E24>Outliers!$J$13,Outliers!E24<Outliers!$K$13) -> FALSE
A25: 93863.75 | B25: 127320.38 | C25: 249839.44 | D25: Florida | E25: 141585.52 | F25: =OR(Outliers!E25>Outliers!$J$13,Outliers!E25<Outliers!$K$13) -> FALSE
... A61: 542.05 | B61: 51743.15 | C61: 0 | D61: New York | E61: 35673.41 | F61: =OR(Outliers!E61>Outliers!$J$13,Outliers!E61<Outliers!$K$13) -> FALSE
A62: 0 | B62: 116983.8 | C62: 45173.06 | D62: California | E62: 14681.4 | F62: =OR(Outliers!E62>Outliers!$J$13,Outliers!E62<Outliers!$K$13) -> TRUE | I62: OUTLIER
A65: During data preprocessing, I identified one outlier in the Profit column. To handle it, I replaced the outlier with the mean value of the Profit column so that the data becomes more consistent and does not distort the analysis | Q65: During data preprocessing, I identified one outlier in the Profit column. To handle it, I replaced the outlier with the mean value of the Profit column so that the data becomes more consistent and does not distort the analysis | U65: During data preprocessing, I identified one outlier in the Profit column. To handle it, I replaced the outlier with the mean value of the Profit column so that the data becomes more consistent and does not distort the analysis | AK65: During data preprocessing, I identified one outlier in the Profit column. To handle it, I replaced the outlier with the mean value of the Profit column so that the data becomes more consistent and does not distort the analysis
A68: RD_Spend | B68: Administration | C68: Marketing_Spend | D68: State | E68: Profit
A69: 165349.2 | B69: 136897.8 | C69: 471784.1 | D69: New York | E69: 192261.83
A70: 162597.7 | B70: 151377.59 | C70: 443898.53 | D70: California | E70: 191792.06
A71: 153441.51 | B71: 101145.55 | C71: 407934.54 | D71: Florida | E71: 191050.39
A72: 144372.41 | B72: 118671.85 | C72: 383199.62 | D72: New York | E72: 182901.99
A73: 142107.34 | B73: 91391.77 | C73: 366168.42 | D73: Florida | E73: 166187.94
A74: 131876.9 | B74: 99814.71 | C74: 362861.36 | D74: New York | E74: 156991.12
A75: 134615.46 | B75: 147198.87 | C75: 127716.82 | D75: California | E75: 156122.51
A76: 130298.13 | B76: 145530.06 | C76: 323876.68 | D76: Florida | E76: 155752.6
A77: 120542.52 | B77: 148718.95 | C77: 311613.29 | D77: New York | E77: 152211.77
A78: 123334.88 | B78: 108679.17 | C78: 304981.62 | D78: California | E78: 149759.96
A79: 101913.08 | B79: 110594.11 | C79: 229160.95 | D79: Florida | E79: 146121.95
A80: 100671.96 | B80: 91790.61 | C80: 249744.55 | D80: California | E80: 144259.4
... A118: 0 | B118: 116983.8 | C118: 45173.06 | D118: California | E118: 112012.6

Sheet Cleaned_data
A1: RD_Spend | B1: Administration | C1: Marketing_Spend | D1: State | E1: Profit
A2: 165349.2 | B2: 136897.8 | C2: 471784.1 | D2: New York | E2: 192261.83
A3: 162597.7 | B3: 151377.59 | C3: 443898.53 | D3: California | E3: 191792.06
A4: 153441.51 | B4: 101145.55 | C4: 407934.54 | D4: Florida | E4: 191050.39
A5: 144372.41 | B5: 118671.85 | C5: 383199.62 | D5: New York | E5: 182901.99
A6: 142107.34 | B6: 91391.77 | C6: 366168.42 | D6: Florida | E6: 166187.94
A7: 131876.9 | B7: 99814.71 | C7: 362861.36 | D7: New York | E7: 156991.12
A8: 134615.46 | B8: 147198.87 | C8: 127716.82 | D8: California | E8: 156122.51
A9: 130298.13 | B9: 145530.06 | C9: 323876.68 | D9: Florida | E9: 155752.6
A10: 120542.52 | B10: 148718.95 | C10: 311613.29 | D10: New York | E10: 152211.77
A11: 123334.88 | B11: 108679.17 | C11: 304981.62 | D11: California | E11: 149759.96
A12: 101913.08 | B12: 110594.11 | C12: 229160.95 | D12: Florida | E12: 146121.95
A13: 100671.96 | B13: 91790.61 | C13: 249744.55 | D13: California | E13: 144259.4
... A51: 0 | B51: 116983.8 | C51: 45173.06 | D51: California | E51: 112012.6

Sheet Regression_analysis
A1: 1. Get data from the database with the given credentials.
A2: 2. Perform Regression Analysis for the given data to identify how the money spent on Marketing, R&D, and Administration is affecting the company’s Profit. Predict the Profit for the below-given input features.
A4: R&D Spend | B4: Administration | C4: Marketing Spend | D4: Profit
A5: 21892.92 | B5: 81910.77 | C5: 164270.7
A6: 23940.93 | B6: 96489.63 | C6: 137001.1
A8: Controllable Variables are :------ RD_Spend, Administration, Marketing_Spend,
A9: Target Variable :------- Profit
A12: RD_Spend | B12: Administration | C12: Marketing_Spend | D12: State | E12: Profit
A13: 165349.2 | B13: 136897.8 | C13: 471784.1 | D13: New York | E13: 192261.83
A14: 162597.7 | B14: 151377.59 | C14: 443898.53 | D14: California | E14: 191792.06 | G14: To find relation between independent variables and target variable will have to refer Regression analysis equation ------ mx+c
A15: 153441.51 | B15: 101145.55 | C15: 407934.54 | D15: Florida | E15: 191050.39 | G15: where m is Coefficient and C is slope
A16: 144372.41 | B16: 118671.85 | C16: 383199.62 | D16: New York | E16: 182901.99 | G16: As "State" is categorical (New York, California, Florida), as of now it will be considered as dummy variable.
A17: 142107.34 | B17: 91391.77 | C17: 366168.42 | D17: Florida | E17: 166187.94 | G17: Correlation between R&D, Marketing, Admin vs. Profit.
A18: 131876.9 | B18: 99814.71 | C18: 362861.36 | D18: New York | E18: 156991.12
A19: 134615.46 | B19: 147198.87 | C19: 127716.82 | D19: California | E19: 156122.51
A20: 130298.13 | B20: 145530.06 | C20: 323876.68 | D20: Florida | E20: 155752.6 | G20: Y=m1x1+m2x2+m3x3+C
A21: 120542.52 | B21: 148718.95 | C21: 311613.29 | D21: New York | E21: 152211.77 | G21: x1=RD_Spend
A22: 123334.88 | B22: 108679.17 | C22: 304981.62 | D22: California | E22: 149759.96 | G22: x2=Administration
A23: 101913.08 | B23: 110594.11 | C23: 229160.95 | D23: Florida | E23: 146121.95 | G23: x3=Marketing_spend
A24: 100671.96 | B24: 91790.61 | C24: 249744.55 | D24: California | E24: 144259.4
A25: 93863.75 | B25: 127320.38 | C25: 249839.44 | D25: Florida | E25: 141585.52 | G25: REGRESSION ANALYSIS
A26: 91992.39 | B26: 135495.07 | C26: 252664.93 | D26: California | E26: 134307.35
A27: 119943.24 | B27: 156547.42 | C27: 256512.92 | D27: Florida | E27: 132602.65 | G27: SUMMARY OUTPUT
A28: 114523.61 | B28: 122616.84 | C28: 261776.23 | D28: New York | E28: 129917.04
A29: 78013.11 | B29: 121597.55 | C29: 264346.06 | D29: California | E29: 126992.93 | G29: Regression Statistics
A30: 94657.16 | B30: 145077.58 | C30: 282574.31 | D30: New York | E30: 125370.37 | G30: Multiple R | H30: 0.95496271
A31: 91749.16 | B31: 114175.79 | C31: 294919.57 | D31: Florida | E31: 124266.9 | G31: R Square | H31: 0.91195378
A32: 86419.7 | B32: 153514.11 | C32: 0 | D32: New York | E32: 122776.86 | G32: Adjusted R Square | H32: 0.90621163
A33: 76253.86 | B33: 113867.3 | C33: 298664.47 | D33: California | E33: 118474.03 | G33: Standard Error | H33: 11570.321
A34: 78389.47 | B34: 153773.43 | C34: 299737.29 | D34: New York | E34: 111313.02 | G34: Observations | H34: 50
A35: 73994.56 | B35: 122782.75 | C35: 303319.26 | D35: Florida | E35: 110352.25
A36: 67532.53 | B36: 105751.03 | C36: 304768.73 | D36: Florida | E36: 108733.99 | G36: ANOVA
A37: 77044.01 | B37: 99281.34 | C37: 140574.81 | D37: New York | E37: 108552.04 | H37: df | I37: SS | J37: MS | K37: F | L37: Significance F
A38: 64664.71 | B38: 139553.16 | C38: 137962.62 | D38: California | E38: 107404.34 | G38: Regression | H38: 3 | I38: 6.3783856e+10 | J38: 2.1261285e+10 | K38: 158.81762 | L38: 2.8151585e-24
A39: 75328.87 | B39: 144135.98 | C39: 134050.07 | D39: Florida | E39: 105733.54 | G39: Residual | H39: 46 | I39: 6.1581273e+09 | J39: 1.3387233e+08
A40: 72107.6 | B40: 127864.55 | C40: 353183.81 | D40: New York | E40: 105008.31 | G40: Total | H40: 49 | I40: 6.9941983e+10
A41: 66051.52 | B41: 182645.56 | C41: 118148.2 | D41: Florida | E41: 103282.38
A42: 65605.48 | B42: 153032.06 | C42: 107138.38 | D42: New York | E42: 101004.64 | H42: Coefficients | I42: Standard Error | J42: t Stat | K42: P-value | L42: Lower 95% | M42: Upper 95% | N42: Lower 95.0% | O42: Upper 95.0%
A43: 61994.48 | B43: 115641.28 | C43: 91131.24 | D43: Florida | E43: 99937.59 | G43: Intercept | H43: 56192.003 | I43: 8236.728 | J43: 6.8221268 | K43: 1.6850312e-08 | L43: 39612.329 | M43: 72771.676 | N43: 39612.329 | O43: 72771.676
A44: 61136.38 | B44: 152701.92 | C44: 88218.23 | D44: New York | E44: 97483.56 | G44: RD_Spend | H44: 0.74471963 | I44: 0.056580315 | J44: 13.162168 | K44: 3.3045903e-17 | L44: 0.63082936 | M44: 0.85860989 | N44: 0.63082936 | O44: 0.85860989
...
